Workbook

Sheet Data Sheet
A1: Sku | B1: Style Code | C1: Colour Code | D1: Option | E1: Category | F1: Material | G1: Style | H1: Range | I1: Colour | J1: Size | K1: Description | L1: Quantity Avilable | M1: Landed Cost Price | N1: Agreed GBP RRP | O1: Vat | P1: Net RRP | Q1: Margin
A2: 900000ZZAUBE0000 | B2: 900000 | C2: AUBE | D2: 900196AUBE | E2: Fingerless Gloves | F2: Cashmere | G2: Cashmere Fingerless Gloves | H2: Core | I2: Aubergine | J2: One Size | K2: Cashmere Fingerless Gloves Aubergine | L2: 0 | M2: 6.95 | N2: 39 | O2: 1.2 | P2: =SUM(N2/O2) | Q2: =((N2/O2)-M2)/(N2/O2)
A3: 900236ZZBLCK0000 | B3: 900236 | C3: BLCK | D3: 900236BLCK | E3: Fingerless Gloves | F3: Cashmere | G3: Cashmere Fingerless Gloves | H3: TBC | I3: Black | J3: One Size | K3: Re:Born Cashmere Fingerless Gloves, Black, O/S | L3: 6600 | M3: 8.2 | N3: 39 | O3: 1.2 | P3: =N3/O3 | Q3: =((N3/O3)-M3)/(N3/O3)
A4: 900236ZZLGRY0000 | B4: 900236 | C4: LGRY | D4: 900236LGRY | E4: Fingerless Gloves | F4: Cashmere | G4: Cashmere Fingerless Gloves | H4: TBC | I4: Light Grey | J4: One Size | K4: Re:Born Cashmere Fingerless Gloves, Light Grey, O/S | L4: 3605 | M4: 8.2 | N4: 39 | O4: 1.2 | P4: =N4/O4 | Q4: =((N4/O4)-M4)/(N4/O4)
A5: 900236ZZDKGR0000 | B5: 900236 | C5: DKGR | D5: 900236DKGR | E5: Fingerless Gloves | F5: Cashmere | G5: Cashmere Fingerless Gloves | H5: TBC | I5: Dark Grey | J5: One Size | K5: Re:Born Cashmere Fingerless Gloves, Dark Grey, O/S | L5: 3599 | M5: 8.2 | N5: 39 | O5: 1.2 | P5: =N5/O5 | Q5: =((N5/O5)-M5)/(N5/O5)
A6: 900236ZZLLBL0000 | B6: 900236 | C6: LLBL | D6: 900236LLBL | E6: Fingerless Gloves | F6: Cashmere | G6: Cashmere Fingerless Gloves | H6: TBC | I6: Light Beige | J6: One Size | K6: Re:Born Cashmere Fingerless Gloves, Light Beige, O/S | L6: 3018 | M6: 8.2 | N6: 39 | O6: 1.2 | P6: =N6/O6 | Q6: =((N6/O6)-M6)/(N6/O6)
A7: 900236ZZLTBR0000 | B7: 900236 | C7: LTBR | D7: 900236LTBR | E7: Fingerless Gloves | F7: Cashmere | G7: Cashmere Fingerless Gloves | H7: TBC | I7: Light Brown | J7: One Size | K7: Re:Born Cashmere Fingerless Gloves, Light Brown, O/S | L7: 1302 | M7: 8.2 | N7: 39 | O7: 1.2 | P7: =N7/O7 | Q7: =((N7/O7)-M7)/(N7/O7)
A8: 900236ZZNAVY0000 | B8: 900236 | C8: NAVY | D8: 900236NAVY | E8: Fingerless Gloves | F8: Cashmere | G8: Cashmere Fingerless Gloves | H8: TBC | I8: Navy | J8: One Size | K8: Re:Born Cashmere Fingerless Gloves, Navy, O/S | L8: 1036 | M8: 8.2 | N8: 39 | O8: 1.2 | P8: =N8/O8 | Q8: =((N8/O8)-M8)/(N8/O8)
A9: 900236ZZLMLL0000 | B9: 900236 | C9: LMLL | D9: 900236LMLL | E9: Fingerless Gloves | F9: Cashmere | G9: Cashmere Fingerless Gloves | H9: TBC | I9: Light Maroon | J9: One Size | K9: Re:Born Cashmere Fingerless Gloves, Light Maroon, O/S | L9: 991 | M9: 8.2 | N9: 39 | O9: 1.2 | P9: =N9/O9 | Q9: =((N9/O9)-M9)/(N9/O9)
A10: 900236ZZRDST0000 | B10: 900236 | C10: RDST | D10: 900236RDST | E10: Fingerless Gloves | F10: Cashmere | G10: Cashmere Fingerless Gloves | H10: TBC | I10: Red | J10: One Size | K10: Re:Born Cashmere Fingerless Gloves, Red, O/S | L10: 988 | M10: 8.2 | N10: 39 | O10: 1.2 | P10: =N10/O10 | Q10: =((N10/O10)-M10)/(N10/O10)
A11: 900236ZZAAAC0000 | B11: 900236 | C11: AAAC | D11: 900236AAAC | E11: Fingerless Gloves | F11: Cashmere | G11: Cashmere Fingerless Gloves | H11: TBC | I11: Baby Pink | J11: One Size | K11: Re:Born Cashmere Fingerless Gloves, Baby Pink, O/S | L11: 800 | M11: 8.2 | N11: 39 | O11: 1.2 | P11: =N11/O11 | Q11: =((N11/O11)-M11)/(N11/O11)
A12: 900236ZZDKBR0000 | B12: 900236 | C12: DKBR | D12: 900236DKBR | E12: Fingerless Gloves | F12: Cashmere | G12: Cashmere Fingerless Gloves | H12: TBC | I12: Dark Brown | J12: One Size | K12: Re:Born Cashmere Fingerless Gloves, Dark Brown, O/S | L12: 740 | M12: 8.2 | N12: 39 | O12: 1.2 | P12: =N12/O12 | Q12: =((N12/O12)-M12)/(N12/O12)
A13: 900236ZZYELL0000 | B13: 900236 | C13: YELL | D13: 900236YELL | E13: Fingerless Gloves | F13: Cashmere | G13: Cashmere Fingerless Gloves | H13: TBC | I13: Yellow | J13: One Size | K13: Re:Born Cashmere Fingerless Gloves, Yellow, O/S | L13: 736 | M13: 8.2 | N13: 39 | O13: 1.2 | P13: =N13/O13 | Q13: =((N13/O13)-M13)/(N13/O13)
A14: 900236ZZBEIG0000 | B14: 900236 | C14: BEIG | D14: 900236BEIG | E14: Fingerless Gloves | F14: Cashmere | G14: Cashmere Fingerless Gloves | H14: TBC | I14: Beige | J14: One Size | K14: Re:Born Cashmere Fingerless Gloves, Beige, O/S | L14: 624 | M14: 8.2 | N14: 39 | O14: 1.2 | P14: =N14/O14 | Q14: =((N14/O14)-M14)/(N14/O14)
... A23: 900236ZZKELL0000 | B23: 900236 | C23: KELL | D23: 900236KELL | E23: Fingerless Gloves | F23: Cashmere | G23: Cashmere Fingerless Gloves | H23: TBC | I23: Kelly Green | J23: One Size | K23: Re:Born Cashmere Fingerless Gloves, Kelly Green, O/S | L23: 121 | M23: 8.2 | N23: 39 | O23: 1.2 | P23: =N23/O23 | Q23: =((N23/O23)-M23)/(N23/O23)
A24: 900234ZZAADP0000 | B24: 900234 | C24: AADP | D24: 900234AADP | E24: Beanie & Glove Set | F24: Cashmere | G24: Cashmere Beanie & Glove Set | H24: TBC | I24: Black & Red | J24: One Size | K24: Re:Born Beanie & Glove Set, Black & Red, O/S | L24: 117 | M24: 17.2 | N24: TBC | O24: 1.2 | P24: TBC | Q24: TBC
A25: 900235ZZREAA0000 | B25: 900235 | C25: REAA | D25: 900235REAA | E25: 2 Pack Gloves | F25: Cashmere | G25: Cashmere 2 Pack Gloves | H25: TBC | I25: Red And Navy | J25: One Size | K25: Re:Born 2 Pack Gloves, Red And Navy, O/S | L25: 98 | M25: TBC | N25: TBC | O25: TBC | P25: TBC | Q25: TBC
A26: 900236ZZAAAK0000 | B26: 900236 | C26: AAAK | D26: 900236AAAK | E26: Fingerless Gloves | F26: Cashmere | G26: Cashmere Fingerless Gloves | H26: TBC | I26: Hot Pink | J26: One Size | K26: Re:Born Cashmere Fingerless Gloves, Hot Pink, O/S | L26: 81 | M26: 8.2 | N26: 39 | O26: 1.2 | P26: =N26/O26 | Q26: =((N26/O26)-M26)/(N26/O26)
A27: 900235ZZBCAA0000 | B27: 900235 | C27: BCAA | D27: 900235BCAA | E27: 2 Pack Gloves | F27: Cashmere | G27: Cashmere 2 Pack Gloves | H27: TBC | I27: Black And Caramel | J27: One Size | K27: Re:Born 2 Pack Gloves, Black And Caramel, O/S | L27: 41 | M27: TBC | N27: TBC | O27: TBC | P27: TBC | Q27: TBC
A28: 900236ZZAADI0000 | B28: 900236 | C28: AADI | D28: 900236AADI | E28: Fingerless Gloves | F28: Cashmere | G28: Cashmere Fingerless Gloves | H28: TBC | I28: One Of A Kind | J28: One Size | K28: Re:Born Cashmere Fingerless Gloves, One Of A Kind, O/S | L28: 41 | M28: 8.2 | N28: 39 | O28: 1.2 | P28: =N28/O28 | Q28: =((N28/O28)-M28)/(N28/O28)
A29: 900236ZZBRRR0000 | B29: 900236 | C29: BRRR | D29: 900236BRRR | E29: Fingerless Gloves | F29: Cashmere | G29: Cashmere Fingerless Gloves | H29: TBC | I29: Brights | J29: One Size | K29: Re:Born Cashmere Fingerless Gloves, Brights, O/S | L29: 33 | M29: 8.2 | N29: 39 | O29: 1.2 | P29: =N29/O29 | Q29: =((N29/O29)-M29)/(N29/O29)
A30: 900234ZZNBAN0000 | B30: 900234 | C30: NBAN | D30: 900234NBAN | E30: Beanie & Glove Set | F30: Cashmere | G30: Cashmere Beanie & Glove Set | H30: TBC | I30: Navy And Beige | J30: One Size | K30: Re:Born Beanie & Glove Set, Navy And Beige, O/S | L30: 30 | M30: 17.2 | N30: TBC | O30: 1.2 | P30: TBC | Q30: TBC
A31: 900231ZZLBAL0000 | B31: 900231 | C31: LBAL | D31: 900231LBAL | E31: Reversible Beanie | F31: Cashmere | G31: Cashmere Reversible Beanie | H31: TBC | I31: Light Blue&Light Beige | J31: One Size | K31: Re:Born Reversible Cashmere Beanie, Light Blue&Light Beige, O/S | L31: 13 | M31: 9.1 | N31: 39 | O31: 1.2 | P31: =N31/O31 | Q31: =((N31/O31)-M31)/(N31/O31)
A32: 900231ZZBLLL0000 | B32: 900231 | C32: BLLL | D32: 900231BLLL | E32: Reversible Beanie | F32: Cashmere | G32: Cashmere Reversible Beanie | H32: TBC | I32: Black And Light Grey | J32: One Size | K32: Re:Born Reversible Cashmere Beanie, Black And Light Grey, O/S | L32: 11 | M32: 9.1 | N32: 39 | O32: 1.2 | P32: =N32/O32 | Q32: =((N32/O32)-M32)/(N32/O32)
A33: 900236ZZAAAH0000 | B33: 900236 | C33: AAAH | D33: 900236AAAH | E33: Fingerless Gloves | F33: Cashmere | G33: Cashmere Fingerless Gloves | H33: TBC | I33: Orange | J33: One Size | K33: Re:Born Cashmere Fingerless Gloves, Orange, O/S | L33: 7 | M33: 8.2 | N33: 39 | O33: 1.2 | P33: =N33/O33 | Q33: =((N33/O33)-M33)/(N33/O33)
A34: 900236ZZROBU0000 | B34: 900236 | C34: ROBU | D34: 900236ROBU | E34: Fingerless Gloves | F34: Cashmere | G34: Cashmere Fingerless Gloves | H34: TBC | I34: Royal Blue | J34: One Size | K34: Re:Born Cashmere Fingerless Gloves, Royal Blue, O/S | L34: 7 | M34: 8.2 | N34: 39 | O34: 1.2 | P34: =N34/O34 | Q34: =((N34/O34)-M34)/(N34/O34)
A35: 900232ZZLCAA0000 | B35: 900232 | C35: LCAA | D35: 900232LCAA | E35: Reversible Snood | F35: Cashmere | G35: Cashmere Reversible Snood | H35: TBC | I35: Light Beige&Choco Brown | J35: One Size | K35: Re:Born Reversible Cashmere Snood, Light Beige&Choco Brown, O/S | L35: 55 | M35: 9.1 | N35: 42 | O35: 1.2 | P35: =N35/O35 | Q35: =((N35/O35)-M35)/(N35/O35)
A36: 900231ZZBPAA0000 | B36: 900231 | C36: BPAA | D36: 900231BPAA | E36: Reversible Beanie | F36: Cashmere | G36: Cashmere Reversible Beanie | H36: TBC | I36: Baby Pink And Cream | J36: One Size | K36: Re:Born Reversible Cashmere Beanie, Baby Pink And Cream, O/S | L36: 49 | M36: 9.1 | N36: 39 | O36: 1.2 | P36: =N36/O36 | Q36: =((N36/O36)-M36)/(N36/O36)
A37: 900231ZZPYPP0000 | B37: 900231 | C37: PYPP | D37: 900231PYPP | E37: Reversible Beanie | F37: Cashmere | G37: Cashmere Reversible Beanie | H37: TBC | I37: Purple And Yellow | J37: One Size | K37: Re:Born Reversible Cashmere Beanie, Purple And Yellow, O/S | L37: 7 | M37: 9.1 | N37: 39 | O37: 1.2 | P37: =N37/O37 | Q37: =((N37/O37)-M37)/(N37/O37)
A38: 900231ZZREAR0000 | B38: 900231 | C38: REAR | D38: 900231REAR | E38: Reversible Beanie | F38: Cashmere | G38: Cashmere Reversible Beanie | H38: TBC | I38: Red And Beige | J38: One Size | K38: Re:Born Reversible Cashmere Beanie, Red And Beige, O/S | L38: 26 | M38: 9.1 | N38: 39 | O38: 1.2 | P38: =N38/O38 | Q38: =((N38/O38)-M38)/(N38/O38)
A39: 900232ZZBBRA0000 | B39: 900232 | C39: BBRA | D39: 900232BBRA | E39: Reversible Snood | F39: Cashmere | G39: Cashmere Reversible Snood | H39: TBC | I39: Beige And Brown | J39: One Size | K39: Re:Born Reversible Cashmere Snood, Beige And Brown, O/S | L39: 10 | M39: 9.1 | N39: 42 | O39: 1.2 | P39: =N39/O39 | Q39: =((N39/O39)-M39)/(N39/O39)
A40: 900232ZZBGAA0000 | B40: 900232 | C40: BGAA | D40: 900232BGAA | E40: Reversible Snood | F40: Cashmere | G40: Cashmere Reversible Snood | H40: TBC | I40: Black And Dark Grey | J40: One Size | K40: Re:Born Reversible Cashmere Snood, Black And Dark Grey, O/S | L40: 11 | M40: 9.1 | N40: 42 | O40: 1.2 | P40: =N40/O40 | Q40: =((N40/O40)-M40)/(N40/O40)
A41: 900232ZZBLCK0000 | B41: 900232 | C41: BLCK | D41: 900232BLCK | E41: Reversible Snood | F41: Cashmere | G41: Cashmere Reversible Snood | H41: TBC | I41: Black | J41: One Size | K41: Re:Born Reversible Cashmere Snood, Black, O/S | L41: 128 | M41: 9.1 | N41: 42 | O41: 1.2 | P41: =N41/O41 | Q41: =((N41/O41)-M41)/(N41/O41)
A42: 900232ZZLBAA0000 | B42: 900232 | C42: LBAA | D42: 900232LBAA | E42: Reversible Snood | F42: Cashmere | G42: Cashmere Reversible Snood | H42: TBC | I42: Light Grey And Black | J42: One Size | K42: Re:Born Reversible Cashmere Snood, Light Grey And Black, O/S | L42: 138 | M42: 9.1 | N42: 42 | O42: 1.2 | P42: =N42/O42 | Q42: =((N42/O42)-M42)/(N42/O42)
... A44: 900232ZZRCCC0000 | B44: 900232 | C44: RCCC | D44: 900232RCCC | E44: Reversible Snood | F44: Cashmere | G44: Cashmere Reversible Snood | H44: TBC | I44: Red And Cream | J44: One Size | K44: Re:Born Reversible Cashmere Snood, Red And Cream, O/S | L44: 34 | M44: 9.1 | N44: 42 | O44: 1.2 | P44: =N44/O44 | Q44: =((N44/O44)-M44)/(N44/O44)
A45: 900233ZZNRAN0000 | B45: 900233 | C45: NRAN | D45: 900233NRAN | E45: Snood & Glove Set | F45: Cashmere | G45: Cashmere Snood & Glove Set | H45: TBC | I45: Navy/Red and Grey | J45: One Size | K45: Re:Born Snood & Glove Set, Navy/Red and Grey, O/S | L45: 35 | M45: 17.2 | N45: TBC | O45: 1.2 | P45: TBC | Q45: TBC
A46: 900236ZZGRRR0000 | B46: 900236 | C46: GRRR | D46: 900236GRRR | E46: Fingerless Gloves | F46: Cashmere | G46: Cashmere Fingerless Gloves | H46: TBC | I46: Grape Purple | J46: One Size | K46: Re:Born Cashmere Fingerless Gloves, Grape Purple, O/S | L46: 277 | M46: 8.2 | N46: 39 | O46: 1.2 | P46: =N46/O46 | Q46: =((N46/O46)-M46)/(N46/O46)
A47: 900236ZZDKPU0000 | B47: 900236 | C47: DKPU | D47: 900236DKPU | E47: Fingerless Gloves | F47: Cashmere | G47: Cashmere Fingerless Gloves | H47: TBC | I47: Dark Purple | J47: One Size | K47: Re:Born Cashmere Fingerless Gloves, Dark Purple, O/S | L47: 230 | M47: 8.2 | N47: 39 | O47: 1.2 | P47: =N47/O47 | Q47: =((N47/O47)-M47)/(N47/O47)
A48: 900236ZZOCAA0000 | B48: 900236 | C48: OCAA | D48: 900236OCAA | E48: Fingerless Gloves | F48: Cashmere | G48: Cashmere Fingerless Gloves | H48: TBC | I48: Ocean Green | J48: One Size | K48: Re:Born Cashmere Fingerless Gloves, Ocean Green, O/S | L48: 229 | M48: 8.2 | N48: 39 | O48: 1.2 | P48: =N48/O48 | Q48: =((N48/O48)-M48)/(N48/O48)
A49: 900236ZZBABB0000 | B49: 900236 | C49: BABB | D49: 900236BABB | E49: Fingerless Gloves | F49: Cashmere | G49: Cashmere Fingerless Gloves | H49: TBC | I49: Baby Blue | J49: One Size | K49: Re:Born Cashmere Fingerless Gloves, Baby Blue, O/S | L49: 161 | M49: 8.2 | N49: 39 | O49: 1.2 | P49: =N49/O49 | Q49: =((N49/O49)-M49)/(N49/O49)
...

Sheet ReBorn
A1: Description | B1: Cost Price | C1: RRP | D1: Vat | E1: Country of Origin
A2: Re:Born Cashmere Headband | B2: 7.1 | C2: 25 | D2: 1.2 | E2: Dubai
A3: Re:Born Reversible Cashmere Beanie | B3: 9.1 | C3: 39 | D3: 1.2 | E3: Dubai
A4: Re:Born Reversible Cashmere Snood | B4: 9.1 | C4: 42 | D4: 1.2 | E4: Dubai
A5: Re:Born Snood & Glove Set | B5: 17.2 | C5: ? | D5: 1.2 | E5: Dubai
A6: Re:Born Beanie & Glove Set | B6: 17.2 | C6: ? | D6: 1.2 | E6: Dubai
A7: Re:Born Cashmere Fingerless Gloves | B7: 8.2 | C7: 39 | D7: 1.2 | E7: Dubai

Sheet Summary
A1: Re:Born Stock List – Summary Answers
A3: Q1. Total stock at net value | B3: =SUMPRODUCT(N('Data Sheet'!P3:P52),'Data Sheet'!L3:L52)
A4: (of which, units excluded - price not yet confirmed, see notes) | B4: =SUMPRODUCT((('Data Sheet'!P3:P52="TBC"))*'Data Sheet'!L3:L52)
A6: Q2. Fingerless Gloves currently in stock | B6: =SUMIF('Data Sheet'!E3:E52,"Fingerless Gloves",'Data Sheet'!L3:L52)
A8: Stock quantity by category (reference)
A9: Fingerless Gloves | B9: =SUMIF('Data Sheet'!E3:E52,"Fingerless Gloves",'Data Sheet'!L3:L52)
A10: Reversible Beanie | B10: =SUMIF('Data Sheet'!E3:E52,"Reversible Beanie",'Data Sheet'!L3:L52)
A11: Reversible Snood | B11: =SUMIF('Data Sheet'!E3:E52,"Reversible Snood",'Data Sheet'!L3:L52)
A12: Snood & Glove Set | B12: =SUMIF('Data Sheet'!E3:E52,"Snood & Glove Set",'Data Sheet'!L3:L52)
A13: Beanie & Glove Set | B13: =SUMIF('Data Sheet'!E3:E52,"Beanie & Glove Set",'Data Sheet'!L3:L52)
A14: 2 Pack Gloves | B14: =SUMIF('Data Sheet'!E3:E52,"2 Pack Gloves",'Data Sheet'!L3:L52)
A16: Notes:
A17: Net value = Quantity Available x Net RRP, summed across all rows with a confirmed RRP.
A18: 35 (Snood & Glove Set) + 147 (Beanie & Glove Set) + 139 (2 Pack Gloves) = 321 units are excluded
A19: from the net-value total because their RRP is not yet confirmed (see 'Cleaning Log' tab).
A20: All figures recalculate automatically from the 'Data Sheet' tab.

Sheet Cleaning Log
A1: Data Cleaning Log - Re:Born Stock List
A3: Original Row(s) | B3: Issue Found | C3: Resolution | D3: Type
A4: Row 41 | B4: Completely blank row in the middle of the sheet. | C4: Row removed. | D4: Blank row
A5: Rows 4 & 5 | B5: Sku 900236ZZLGRY0000 listed twice with identical qty (3605) and identical description. | C5: Kept row 4, removed the exact duplicate. | D5: Exact duplicate
A6: Rows 6 & 7 | B6: Sku 900236ZZDKGR0000 listed twice with identical qty (3599) and identical description. | C6: Kept row 6, removed the exact duplicate. | D6: Exact duplicate
A7: Rows 58 & 59 | B7: Sku 900236ZZAAAI0000 (Teal) listed twice with identical qty (138) and identical description. | C7: Kept row 58, removed the exact duplicate. | D7: Exact duplicate
A8: Rows 17 & 18 | B8: Sku 900236ZZDMAA0000 listed twice, same qty (598), but row 18's description drops the word 'Fingerless' and uses 'One Size' instead of 'O/S'. | C8: Kept row 17 (matches the standard description format used everywhere else), removed row 18. | D8: Duplicate - inconsistent wording
A9: Rows 30 & 31 | B9: Sku 900235ZZBCAA0000 listed twice, same qty (41); row 31 spells the brand 'RE:Born' (wrong capitalisation) instead of 'Re:Born'. | C9: Kept row 30, removed the typo duplicate. | D9: Duplicate - typo
A10: Rows 36 & 47 | B10: Sku 900232ZZBGAA0000 listed twice (not adjacent - easy to miss), same qty (11); row 36 has a double space and is 8 rows away from its duplicate at row 47. | C10: Kept row 47, removed row 36. | D10: Duplicate - formatting/typo, non-adjacent
A11: Rows 37 & 38 | B11: Sku 900231ZZBLLL0000 listed twice, same qty (11); row 37 drops the word 'Cashmere' and has a double space. | C11: Kept row 38, removed row 37. | D11: Duplicate - inconsistent wording
A12: Rows 43 & 53 | B12: Sku 900231ZZBPAA0000 listed twice, same qty (49), 10 rows apart; row 53 misspells the brand as 'Re:Bron'. | C12: Kept row 43, removed row 53. | D12: Duplicate - typo, non-adjacent
A13: All Reversible Beanie rows | B13: Product name inconsistently written as 'Reverse Beanie' / 'Reverse Cashmere Beanie' in some rows vs 'Reversible Cashmere Beanie' in others. The ReBorn reference tab confirms 'Reversible' is correct. | C13: Standardised every row's Description to 'Re:Born Reversible Cashmere Beanie, <colour>, O/S'. | D13: Inconsistent naming
A14: Style Code / Colour Code / Option (cols B-D) | B14: Not filled in for any row except the example (row 2). Also, row 2's own Option (900196AUBE) does not actually match its own Style Code (900000) or Sku - the example itself contains an inconsistency. | C14: Derived Style Code and Colour Code directly from each Sku (first 6 digits / the 4 letters between 'ZZ' and the trailing '0000'), and built Option as Style Code + Colour Code consistently for every row. | D14: Missing data + example inconsistency
... A22: Range (col H) | B22: The row 2 example shows a Range of 'Core', but no other row, sheet, or column in the source data indicates what Range/Collection any product belongs to. | C22: Left as 'TBC' (highlighted) for every row rather than guessing. Recommend checking with merchandising for the correct Range per style. | D22: Further investigation needed
